Workbook

Sheet Start Here
A1: Iconic Events: Case Study Collection Sheet
A2: One workbook for all six case studies. Fill the yellow cells. Everything else is calculated or locked.
A4: How to use
B5: Work tab by tab, not event by event. Pulling all six sets of numbers in one sitting is much faster than
B6: compiling one event end to end, six times.
A8: Event Facts | B8: One row per event. Columns C to M are required before a page can publish.
A9: Photos | B9: Eight positions per event. Mark each ON FILE or NEEDED and name the file.
A10: Quotes | B10: Client quote and permission. A page publishes fine without this, so it never blocks launch.
A11: Decisions | B11: Three questions Iconic answers once, not per event. All three affect all six pages.
A13: Legend
A14: Yellow cell | B14: Fill this in.
A15: Grey cell | B15: Locked. Do not edit: it keys to the code.
A16: Cream row | B16: Worked example showing the expected format.
A18: House rules
B19: Only three metrics are ever published: attendance, days of production, cost saved for the client.
B20: Never published: client revenue, sponsorship dollars, revenue per seat, lead count, repeat booking.
B21: No budget figure or range is ever published. There is no column for it.
B22: Nothing is estimated. Leave a cell blank rather than guessing; a blank renders as nothing on the page.
B23: No em dashes in any published copy.
A25: Progress
A26: Event | B26: Required facts missing | C26: Photos needed | D26: Quote ready
A27: Casino Royale | B27: ='Event Facts'!R4 | C27: =COUNTIFS(Photos!$A$4:$A$51,$A27,Photos!$F$4:$F$51,"NEEDED") | D27: =Quotes!G3
A28: Bad After Dark | B28: ='Event Facts'!R5 | C28: =COUNTIFS(Photos!$A$4:$A$51,$A28,Photos!$F$4:$F$51,"NEEDED") | D28: =Quotes!G4
A29: The CEO Lawyer Summit | B29: ='Event Facts'!R6 | C29: =COUNTIFS(Photos!$A$4:$A$51,$A29,Photos!$F$4:$F$51,"NEEDED") | D29: =Quotes!G5
A30: Scaling With Systems LIVE | B30: ='Event Facts'!R7 | C30: =COUNTIFS(Photos!$A$4:$A$51,$A30,Photos!$F$4:$F$51,"NEEDED") | D30: =Quotes!G6
A31: Viral Ecom Adz | B31: ='Event Facts'!R8 | C31: =COUNTIFS(Photos!$A$4:$A$51,$A31,Photos!$F$4:$F$51,"NEEDED") | D31: =Quotes!G7
A32: Chase Hughes, London | B32: ='Event Facts'!R9 | C32: =COUNTIFS(Photos!$A$4:$A$51,$A32,Photos!$F$4:$F$51,"NEEDED") | D32: =Quotes!G8
A33: Total | B33: =SUM(B27:B32) | C33: =SUM(C27:C32)

Sheet Event Facts
A1: Event Facts
A2: Event | B2: Slug (locked) | C2: Client name | D2: Venue | E2: City | F2: State or country | G2: Year | H2: Exact dates (YYYY-MM-DD) | I2: Attendance | J2: Days of production | K2: Cost saved (USD) | L2: How the saving was calculated | M2: Aftermovie URL | N2: Testimonial video URL | O2: Client job title and company | P2: Weeks of planning | Q2: Vendors Iconic managed directly | R2: Required missing
A3: EXAMPLE (do not edit) | B3: example-slug | C3: Jane Doe | D3: The Grand Hall | E3: Miami | F3: FL | G3: 2025 | H3: 2025-04-18 | I3: 220 | J3: 4 | K3: 85000 | L3: Consolidated scope vs itemised vendor quotes | M3: https://www.youtube.com/watch?v=XXXXXXXXXXX | N3: https://www.youtube.com/watch?v=YYYYYYYYYYY | O3: Founder, Doe Group | P3: 26 | Q3: AV, lighting, staging, catering | R3: =COUNTBLANK(C3:M3)
A4: Casino Royale | B4: casino-royale | C4: Ben Newman | D4: Palms Casino Resort | E4: Las Vegas | F4: NV | G4: 2023 | I4: 150 | J4: 3 | K4: 100000 | M4: https://www.youtube.com/watch?v=CmrSzYrgTWY | N4: https://www.youtube.com/watch?v=3XTRiuOMD4k | R4: =COUNTBLANK(C4:M4)
A5: Bad After Dark | B5: bad-after-dark | C5: Eddie Maalouf | R5: =COUNTBLANK(C5:M5)
A6: The CEO Lawyer Summit | B6: ceo-lawyer-summit | C6: Ali Awad | R6: =COUNTBLANK(C6:M6)
A7: Scaling With Systems LIVE | B7: scaling-with-systems-live | C7: Ravi Abuvala | R7: =COUNTBLANK(C7:M7)
A8: Viral Ecom Adz | B8: viral-ecom-adz | R8: =COUNTBLANK(C8:M8)
A9: Chase Hughes, London | B9: chase-hughes-london | C9: Chase Hughes | D9: HMS Belfast, River Thames | E9: London | F9: United Kingdom | R9: =COUNTBLANK(C9:M9)
A12: Notes
B13: Columns C to M are required. 'Required missing' counts how many of them are still blank.
B14: Cost saved: enter the number only, no currency symbol or comma. 100000, not $100,000.
B15: Casino Royale figures supplied by Iconic: 150 attendees, 3 days of production, $100,000 saved.
B16: Casino Royale testimonial URL was supplied as 'a link for us'. Confirm it is the testimonial, not a second aftermovie.
B17: Casino Royale client title 'Founder, Ben Newman Companies' is assumed and needs confirming, so it is left blank here.
B18: 'How the saving was calculated' must use the same basis on every event, or the headlines will not stand up to scrutiny.

Sheet Photos
A1: Photos: eight positions per event
A2: Mark each position ON FILE or NEEDED. Positions and ratios are fixed by the page template.
A3: Event | B3: # | C3: What it shows | D3: Ratio | E3: Pixel spec | F3: Status | G3: File name or note
A4: Casino Royale | B4: 01 | C4: Hero, room at capacity | D4: 16:9 | E4: 2400x1350, lower third clear of faces | F4: NEEDED
A5: Casino Royale | B5: 02 | C5: The audience, seated | D5: 4:5 | E5: 1200x1500 | F5: ON FILE | G5: g34.webp
A6: Casino Royale | B6: 03 | C6: The build, no people in frame | D6: 21:9 | E6: 2400x1030, full bleed | F6: ON FILE | G6: g31.webp
A7: Casino Royale | B7: 04 | C7: The close, from the floor | D7: 4:3 | E7: 1600x1200 | F7: ON FILE | G7: g32.webp
A8: Casino Royale | B8: 05 | C8: Room wide enough to read attendance | D8: 4:3 | E8: 1600x1200 | F8: NEEDED
A9: Casino Royale | B9: 06 | C9: Gallery frame | D9: 4:3 | E9: 1600x1200 | F9: ON FILE | G9: g9.webp
A10: Casino Royale | B10: 07 | C10: Gallery frame | D10: 4:3 | E10: 1600x1200 | F10: ON FILE | G10: g24.webp
A11: Casino Royale | B11: 08 | C11: Gallery frame | D11: 4:3 | E11: 1600x1200 | F11: ON FILE | G11: g25.webp
A12: Bad After Dark | B12: 01 | C12: Hero, room at capacity | D12: 16:9 | E12: 2400x1350, lower third clear of faces | F12: NEEDED
A13: Bad After Dark | B13: 02 | C13: The audience, seated | D13: 4:5 | E13: 1200x1500 | F13: NEEDED
A14: Bad After Dark | B14: 03 | C14: The build, no people in frame | D14: 21:9 | E14: 2400x1030, full bleed | F14: ON FILE | G14: g28.webp
A15: Bad After Dark | B15: 04 | C15: The close, from the floor | D15: 4:3 | E15: 1600x1200 | F15: ON FILE | G15: g33.webp
A16: Bad After Dark | B16: 05 | C16: Room wide enough to read attendance | D16: 4:3 | E16: 1600x1200 | F16: NEEDED
A17: Bad After Dark | B17: 06 | C17: Gallery frame | D17: 4:3 | E17: 1600x1200 | F17: ON FILE | G17: g35.webp
A18: Bad After Dark | B18: 07 | C18: Gallery frame | D18: 4:3 | E18: 1600x1200 | F18: NEEDED
A19: Bad After Dark | B19: 08 | C19: Gallery frame | D19: 4:3 | E19: 1600x1200 | F19: NEEDED
A20: The CEO Lawyer Summit | B20: 01 | C20: Hero, room at capacity | D20: 16:9 | E20: 2400x1350, lower third clear of faces | F20: NEEDED
A21: The CEO Lawyer Summit | B21: 02 | C21: The audience, seated | D21: 4:5 | E21: 1200x1500 | F21: NEEDED
A22: The CEO Lawyer Summit | B22: 03 | C22: The build, no people in frame | D22: 21:9 | E22: 2400x1030, full bleed | F22: ON FILE | G22: g13.webp
A23: The CEO Lawyer Summit | B23: 04 | C23: The close, from the floor | D23: 4:3 | E23: 1600x1200 | F23: ON FILE | G23: g16.webp
A24: The CEO Lawyer Summit | B24: 05 | C24: Room wide enough to read attendance | D24: 4:3 | E24: 1600x1200 | F24: NEEDED
A25: The CEO Lawyer Summit | B25: 06 | C25: Gallery frame | D25: 4:3 | E25: 1600x1200 | F25: ON FILE | G25: g19.webp
A26: The CEO Lawyer Summit | B26: 07 | C26: Gallery frame | D26: 4:3 | E26: 1600x1200 | F26: NEEDED
A27: The CEO Lawyer Summit | B27: 08 | C27: Gallery frame | D27: 4:3 | E27: 1600x1200 | F27: NEEDED
A28: Scaling With Systems LIVE | B28: 01 | C28: Hero, room at capacity | D28: 16:9 | E28: 2400x1350, lower third clear of faces | F28: NEEDED
A29: Scaling With Systems LIVE | B29: 02 | C29: The audience, seated | D29: 4:5 | E29: 1200x1500 | F29: NEEDED
A30: Scaling With Systems LIVE | B30: 03 | C30: The build, no people in frame | D30: 21:9 | E30: 2400x1030, full bleed | F30: ON FILE | G30: g26.webp
A31: Scaling With Systems LIVE | B31: 04 | C31: The close, from the floor | D31: 4:3 | E31: 1600x1200 | F31: ON FILE | G31: g22.webp
A32: Scaling With Systems LIVE | B32: 05 | C32: Room wide enough to read attendance | D32: 4:3 | E32: 1600x1200 | F32: NEEDED
A33: Scaling With Systems LIVE | B33: 06 | C33: Gallery frame | D33: 4:3 | E33: 1600x1200 | F33: ON FILE | G33: g23.webp
A34: Scaling With Systems LIVE | B34: 07 | C34: Gallery frame | D34: 4:3 | E34: 1600x1200 | F34: NEEDED
A35: Scaling With Systems LIVE | B35: 08 | C35: Gallery frame | D35: 4:3 | E35: 1600x1200 | F35: NEEDED
A36: Viral Ecom Adz | B36: 01 | C36: Hero, room at capacity | D36: 16:9 | E36: 2400x1350, lower third clear of faces | F36: NEEDED
A37: Viral Ecom Adz | B37: 02 | C37: The audience, seated | D37: 4:5 | E37: 1200x1500 | F37: NEEDED
A38: Viral Ecom Adz | B38: 03 | C38: The build, no people in frame | D38: 21:9 | E38: 2400x1030, full bleed | F38: ON FILE | G38: g3.webp
A39: Viral Ecom Adz | B39: 04 | C39: The close, from the floor | D39: 4:3 | E39: 1600x1200 | F39: ON FILE | G39: g2.webp
A40: Viral Ecom Adz | B40: 05 | C40: Room wide enough to read attendance | D40: 4:3 | E40: 1600x1200 | F40: NEEDED
...

Sheet Quotes
A1: Client quotes and permission
A2: Event | B2: Who to ask | C2: Verbatim quote, two sentences | D2: Permission on file | E2: Date received | F2: Job title confirmed | G2: Ready to publish
A3: Casino Royale | B3: Ben Newman | G3: =IF(AND(TRIM(C3)<>"",LOWER(D3)="yes"),"YES","no")
A4: Bad After Dark | B4: Eddie Maalouf | G4: =IF(AND(TRIM(C4)<>"",LOWER(D4)="yes"),"YES","no")
A5: The CEO Lawyer Summit | B5: Ali Awad | G5: =IF(AND(TRIM(C5)<>"",LOWER(D5)="yes"),"YES","no")
A6: Scaling With Systems LIVE | B6: Ravi Abuvala | G6: =IF(AND(TRIM(C6)<>"",LOWER(D6)="yes"),"YES","no")
A7: Viral Ecom Adz | G7: =IF(AND(TRIM(C7)<>"",LOWER(D7)="yes"),"YES","no")
A8: Chase Hughes, London | B8: Chase Hughes | G8: =IF(AND(TRIM(C8)<>"",LOWER(D8)="yes"),"YES","no")
A11: Notes
B12: A page publishes fine with no quote, so this never blocks launch. Ship the pages, add quotes as they arrive.
B13: 'Ready to publish' turns YES only when the quote is filled in and permission is on file.
B14: In the code, set testimonial.approved to true only for events showing YES here.
B15: Ask about what the client needed and what one accountable team was like. Not about revenue or spend:
B16: a quote about money puts a revenue figure back on pages that deliberately carry none.

Sheet Decisions
A1: Decisions Iconic makes once
A2: All three affect all six pages. Worth settling before the collection passes start.
A3: Decision | B3: Why it matters | C3: Your answer
A4: Is the no client revenue rule site wide, or case studies only? | B4: The lander still publishes client revenue in three places: the featured tile stats, the archive tiles, and the In the Room carousel. If the rule is site wide, those need the same treatment.
A5: Do we name third party brands, such as the 007 property? | B5: Internal copy says '007 Casino Royale'. Case study pages say 'Casino Royale themed', because an indexed page courting AI citation carries trademark exposure that internal copy does not.
A6: Where is the site hosted, and is the SPA rewrite configured? | B6: Each case study is a real URL on a single page app. Without a host rewrite of unknown paths to index.html, a visitor or crawler loading /case-studies/<slug> directly gets a 404.
